2024-11-18 14:40:01,361 - INFO - Starting training for TRANSFORMER model
2024-11-18 14:40:01,361 - INFO - Using device: cuda
2024-11-18 14:40:01,361 - INFO - Configuration: {'input_size': 1, 'dec_seq_len': 48, 'dim_val': 128, 'n_encoder_layers': 4, 'n_decoder_layers': 4, 'n_heads': 8, 'dropout_encoder': 0.2, 'dropout_decoder': 0.2, 'dropout_pos_enc': 0.1, 'dim_feedforward_encoder': 512, 'dim_feedforward_decoder': 512, 'num_predicted_features': 1, 'learning_rate': 0.0001, 'epochs': 100}
2024-11-18 14:40:01,416 - ERROR - Error during training: 'value'
2024-11-18 14:40:01,418 - ERROR - Traceback:
Traceback (most recent call last):
  File "C:\Users\Pc\.conda\envs\energy_pred\lib\site-packages\pandas\core\indexes\base.py", line 3653, in get_loc
    return self._engine.get_loc(casted_key)
  File "pandas\_libs\index.pyx", line 147, in pandas._libs.index.IndexEngine.get_loc
  File "pandas\_libs\index.pyx", line 176, in pandas._libs.index.IndexEngine.get_loc
  File "pandas\_libs\hashtable_class_helper.pxi", line 7080, in pandas._libs.hashtable.PyObjectHashTable.get_item
  File "pandas\_libs\hashtable_class_helper.pxi", line 7088, in pandas._libs.hashtable.PyObjectHashTable.get_item
KeyError: 'value'

The above exception was the direct cause of the following exception:

Traceback (most recent call last):
  File "C:\Projects\GradProject\IoT-Based-Energy-Consumption-Prediction-Using-Transformers\train_models.py", line 118, in train_model
    train_loader, val_loader, test_loader = create_dataloaders(
  File "C:\Projects\GradProject\IoT-Based-Energy-Consumption-Prediction-Using-Transformers\utils\data_utils.py", line 196, in create_dataloaders
    seq = df.iloc[i:i+input_sequence_length]['value'].values
  File "C:\Users\Pc\.conda\envs\energy_pred\lib\site-packages\pandas\core\frame.py", line 3761, in __getitem__
    indexer = self.columns.get_loc(key)
  File "C:\Users\Pc\.conda\envs\energy_pred\lib\site-packages\pandas\core\indexes\base.py", line 3655, in get_loc
    raise KeyError(key) from err
KeyError: 'value'

